Workbook

Sheet Company P&L
A1: FruitBlend24 company P&L, THB, Sep 2025 to Aug 2026
A2: Green = sum of the 4 kitchens on 'Kitchen P&L'. Black = formulas. Main gross profit = GP-C (after commission, fruit, packaging + labor and waste).
A4: Line | B4: 2025-09 | C4: 2025-10 | D4: 2025-11 | E4: 2025-12 | F4: 2026-01 | G4: 2026-02 | H4: 2026-03 | I4: 2026-04 | J4: 2026-05 | K4: 2026-06 | L4: 2026-07 | M4: 2026-08 | N4: FY
A5: Cups sold | B5: ='Kitchen P&L'!B6+'Kitchen P&L'!B28+'Kitchen P&L'!B50+'Kitchen P&L'!B72 | C5: ='Kitchen P&L'!C6+'Kitchen P&L'!C28+'Kitchen P&L'!C50+'Kitchen P&L'!C72 | D5: ='Kitchen P&L'!D6+'Kitchen P&L'!D28+'Kitchen P&L'!D50+'Kitchen P&L'!D72 | E5: ='Kitchen P&L'!E6+'Kitchen P&L'!E28+'Kitchen P&L'!E50+'Kitchen P&L'!E72 | F5: ='Kitchen P&L'!F6+'Kitchen P&L'!F28+'Kitchen P&L'!F50+'Kitchen P&L'!F72 | G5: ='Kitchen P&L'!G6+'Kitchen P&L'!G28+'Kitchen P&L'!G50+'Kitchen P&L'!G72 | H5: ='Kitchen P&L'!H6+'Kitchen P&L'!H28+'Kitchen P&L'!H50+'Kitchen P&L'!H72 | I5: ='Kitchen P&L'!I6+'Kitchen P&L'!I28+'Kitchen P&L'!I50+'Kitchen P&L'!I72 | ... M5: ='Kitchen P&L'!M6+'Kitchen P&L'!M28+'Kitchen P&L'!M50+'Kitchen P&L'!M72 | N5: =SUM(B5:M5)
A6: List revenue | B6: ='Kitchen P&L'!B7+'Kitchen P&L'!B29+'Kitchen P&L'!B51+'Kitchen P&L'!B73 | C6: ='Kitchen P&L'!C7+'Kitchen P&L'!C29+'Kitchen P&L'!C51+'Kitchen P&L'!C73 | D6: ='Kitchen P&L'!D7+'Kitchen P&L'!D29+'Kitchen P&L'!D51+'Kitchen P&L'!D73 | E6: ='Kitchen P&L'!E7+'Kitchen P&L'!E29+'Kitchen P&L'!E51+'Kitchen P&L'!E73 | F6: ='Kitchen P&L'!F7+'Kitchen P&L'!F29+'Kitchen P&L'!F51+'Kitchen P&L'!F73 | G6: ='Kitchen P&L'!G7+'Kitchen P&L'!G29+'Kitchen P&L'!G51+'Kitchen P&L'!G73 | H6: ='Kitchen P&L'!H7+'Kitchen P&L'!H29+'Kitchen P&L'!H51+'Kitchen P&L'!H73 | I6: ='Kitchen P&L'!I7+'Kitchen P&L'!I29+'Kitchen P&L'!I51+'Kitchen P&L'!I73 | ... M6: ='Kitchen P&L'!M7+'Kitchen P&L'!M29+'Kitchen P&L'!M51+'Kitchen P&L'!M73 | N6: =SUM(B6:M6)
A7: Discount | B7: ='Kitchen P&L'!B8+'Kitchen P&L'!B30+'Kitchen P&L'!B52+'Kitchen P&L'!B74 | C7: ='Kitchen P&L'!C8+'Kitchen P&L'!C30+'Kitchen P&L'!C52+'Kitchen P&L'!C74 | D7: ='Kitchen P&L'!D8+'Kitchen P&L'!D30+'Kitchen P&L'!D52+'Kitchen P&L'!D74 | E7: ='Kitchen P&L'!E8+'Kitchen P&L'!E30+'Kitchen P&L'!E52+'Kitchen P&L'!E74 | F7: ='Kitchen P&L'!F8+'Kitchen P&L'!F30+'Kitchen P&L'!F52+'Kitchen P&L'!F74 | G7: ='Kitchen P&L'!G8+'Kitchen P&L'!G30+'Kitchen P&L'!G52+'Kitchen P&L'!G74 | H7: ='Kitchen P&L'!H8+'Kitchen P&L'!H30+'Kitchen P&L'!H52+'Kitchen P&L'!H74 | I7: ='Kitchen P&L'!I8+'Kitchen P&L'!I30+'Kitchen P&L'!I52+'Kitchen P&L'!I74 | ... M7: ='Kitchen P&L'!M8+'Kitchen P&L'!M30+'Kitchen P&L'!M52+'Kitchen P&L'!M74 | N7: =SUM(B7:M7)
A8: Gross revenue | B8: =B6-B7 | C8: =C6-C7 | D8: =D6-D7 | E8: =E6-E7 | F8: =F6-F7 | G8: =G6-G7 | H8: =H6-H7 | I8: =I6-I7 | ... N8: =N6-N7
A9: Commission | B9: ='Kitchen P&L'!B10+'Kitchen P&L'!B32+'Kitchen P&L'!B54+'Kitchen P&L'!B76 | C9: ='Kitchen P&L'!C10+'Kitchen P&L'!C32+'Kitchen P&L'!C54+'Kitchen P&L'!C76 | D9: ='Kitchen P&L'!D10+'Kitchen P&L'!D32+'Kitchen P&L'!D54+'Kitchen P&L'!D76 | E9: ='Kitchen P&L'!E10+'Kitchen P&L'!E32+'Kitchen P&L'!E54+'Kitchen P&L'!E76 | F9: ='Kitchen P&L'!F10+'Kitchen P&L'!F32+'Kitchen P&L'!F54+'Kitchen P&L'!F76 | G9: ='Kitchen P&L'!G10+'Kitchen P&L'!G32+'Kitchen P&L'!G54+'Kitchen P&L'!G76 | H9: ='Kitchen P&L'!H10+'Kitchen P&L'!H32+'Kitchen P&L'!H54+'Kitchen P&L'!H76 | I9: ='Kitchen P&L'!I10+'Kitchen P&L'!I32+'Kitchen P&L'!I54+'Kitchen P&L'!I76 | ... M9: ='Kitchen P&L'!M10+'Kitchen P&L'!M32+'Kitchen P&L'!M54+'Kitchen P&L'!M76 | N9: =SUM(B9:M9)
A10: Net revenue | B10: =B8-B9 | C10: =C8-C9 | D10: =D8-D9 | E10: =E8-E9 | F10: =F8-F9 | G10: =G8-G9 | H10: =H8-H9 | I10: =I8-I9 | ... N10: =N8-N9
A11: Fruit cost | B11: ='Kitchen P&L'!B12+'Kitchen P&L'!B34+'Kitchen P&L'!B56+'Kitchen P&L'!B78 | C11: ='Kitchen P&L'!C12+'Kitchen P&L'!C34+'Kitchen P&L'!C56+'Kitchen P&L'!C78 | D11: ='Kitchen P&L'!D12+'Kitchen P&L'!D34+'Kitchen P&L'!D56+'Kitchen P&L'!D78 | E11: ='Kitchen P&L'!E12+'Kitchen P&L'!E34+'Kitchen P&L'!E56+'Kitchen P&L'!E78 | F11: ='Kitchen P&L'!F12+'Kitchen P&L'!F34+'Kitchen P&L'!F56+'Kitchen P&L'!F78 | G11: ='Kitchen P&L'!G12+'Kitchen P&L'!G34+'Kitchen P&L'!G56+'Kitchen P&L'!G78 | H11: ='Kitchen P&L'!H12+'Kitchen P&L'!H34+'Kitchen P&L'!H56+'Kitchen P&L'!H78 | I11: ='Kitchen P&L'!I12+'Kitchen P&L'!I34+'Kitchen P&L'!I56+'Kitchen P&L'!I78 | ... M11: ='Kitchen P&L'!M12+'Kitchen P&L'!M34+'Kitchen P&L'!M56+'Kitchen P&L'!M78 | N11: =SUM(B11:M11)
A12: Packaging + labor | B12: ='Kitchen P&L'!B13+'Kitchen P&L'!B35+'Kitchen P&L'!B57+'Kitchen P&L'!B79 | C12: ='Kitchen P&L'!C13+'Kitchen P&L'!C35+'Kitchen P&L'!C57+'Kitchen P&L'!C79 | D12: ='Kitchen P&L'!D13+'Kitchen P&L'!D35+'Kitchen P&L'!D57+'Kitchen P&L'!D79 | E12: ='Kitchen P&L'!E13+'Kitchen P&L'!E35+'Kitchen P&L'!E57+'Kitchen P&L'!E79 | F12: ='Kitchen P&L'!F13+'Kitchen P&L'!F35+'Kitchen P&L'!F57+'Kitchen P&L'!F79 | G12: ='Kitchen P&L'!G13+'Kitchen P&L'!G35+'Kitchen P&L'!G57+'Kitchen P&L'!G79 | H12: ='Kitchen P&L'!H13+'Kitchen P&L'!H35+'Kitchen P&L'!H57+'Kitchen P&L'!H79 | I12: ='Kitchen P&L'!I13+'Kitchen P&L'!I35+'Kitchen P&L'!I57+'Kitchen P&L'!I79 | ... M12: ='Kitchen P&L'!M13+'Kitchen P&L'!M35+'Kitchen P&L'!M57+'Kitchen P&L'!M79 | N12: =SUM(B12:M12)
A13: Contribution margin (GP-B) | B13: =B10-B11-B12 | C13: =C10-C11-C12 | D13: =D10-D11-D12 | E13: =E10-E11-E12 | F13: =F10-F11-F12 | G13: =G10-G11-G12 | H13: =H10-H11-H12 | I13: =I10-I11-I12 | ... N13: =N10-N11-N12
A14: Waste cost | B14: ='Kitchen P&L'!B15+'Kitchen P&L'!B37+'Kitchen P&L'!B59+'Kitchen P&L'!B81 | C14: ='Kitchen P&L'!C15+'Kitchen P&L'!C37+'Kitchen P&L'!C59+'Kitchen P&L'!C81 | D14: ='Kitchen P&L'!D15+'Kitchen P&L'!D37+'Kitchen P&L'!D59+'Kitchen P&L'!D81 | E14: ='Kitchen P&L'!E15+'Kitchen P&L'!E37+'Kitchen P&L'!E59+'Kitchen P&L'!E81 | F14: ='Kitchen P&L'!F15+'Kitchen P&L'!F37+'Kitchen P&L'!F59+'Kitchen P&L'!F81 | G14: ='Kitchen P&L'!G15+'Kitchen P&L'!G37+'Kitchen P&L'!G59+'Kitchen P&L'!G81 | H14: ='Kitchen P&L'!H15+'Kitchen P&L'!H37+'Kitchen P&L'!H59+'Kitchen P&L'!H81 | I14: ='Kitchen P&L'!I15+'Kitchen P&L'!I37+'Kitchen P&L'!I59+'Kitchen P&L'!I81 | ... M14: ='Kitchen P&L'!M15+'Kitchen P&L'!M37+'Kitchen P&L'!M59+'Kitchen P&L'!M81 | N14: =SUM(B14:M14)
A15: Gross profit (GP-C) | B15: =B13-B14 | C15: =C13-C14 | D15: =D13-D14 | E15: =E13-E14 | F15: =F13-F14 | G15: =G13-G14 | H15: =H13-H14 | I15: =I13-I14 | ... N15: =N13-N14
A16: Kitchen overhead | B16: ='Kitchen P&L'!B17+'Kitchen P&L'!B39+'Kitchen P&L'!B61+'Kitchen P&L'!B83 | C16: ='Kitchen P&L'!C17+'Kitchen P&L'!C39+'Kitchen P&L'!C61+'Kitchen P&L'!C83 | D16: ='Kitchen P&L'!D17+'Kitchen P&L'!D39+'Kitchen P&L'!D61+'Kitchen P&L'!D83 | E16: ='Kitchen P&L'!E17+'Kitchen P&L'!E39+'Kitchen P&L'!E61+'Kitchen P&L'!E83 | F16: ='Kitchen P&L'!F17+'Kitchen P&L'!F39+'Kitchen P&L'!F61+'Kitchen P&L'!F83 | G16: ='Kitchen P&L'!G17+'Kitchen P&L'!G39+'Kitchen P&L'!G61+'Kitchen P&L'!G83 | H16: ='Kitchen P&L'!H17+'Kitchen P&L'!H39+'Kitchen P&L'!H61+'Kitchen P&L'!H83 | I16: ='Kitchen P&L'!I17+'Kitchen P&L'!I39+'Kitchen P&L'!I61+'Kitchen P&L'!I83 | ... M16: ='Kitchen P&L'!M17+'Kitchen P&L'!M39+'Kitchen P&L'!M61+'Kitchen P&L'!M83 | N16: =SUM(B16:M16)
A17: Operating profit | B17: =B15-B16 | C17: =C15-C16 | D17: =D15-D16 | E17: =E15-E16 | F17: =F15-F16 | G17: =G15-G16 | H17: =H15-H16 | I17: =I15-I16 | ... N17: =N15-N16
A18: GP-C % of gross revenue | B18: =IFERROR(B15/B8,0) | C18: =IFERROR(C15/C8,0) | D18: =IFERROR(D15/D8,0) | E18: =IFERROR(E15/E8,0) | F18: =IFERROR(F15/F8,0) | G18: =IFERROR(G15/G8,0) | H18: =IFERROR(H15/H8,0) | I18: =IFERROR(I15/I8,0) | ... N18: =IFERROR(N15/N8,0)
A19: Operating margin % | B19: =IFERROR(B17/B8,0) | C19: =IFERROR(C17/C8,0) | D19: =IFERROR(D17/D8,0) | E19: =IFERROR(E17/E8,0) | F19: =IFERROR(F17/F8,0) | G19: =IFERROR(G17/G8,0) | H19: =IFERROR(H17/H8,0) | I19: =IFERROR(I17/I8,0) | ... N19: =IFERROR(N17/N8,0)
A20: Commission % of gross revenue | B20: =IFERROR(B9/B8,0) | C20: =IFERROR(C9/C8,0) | D20: =IFERROR(D9/D8,0) | E20: =IFERROR(E9/E8,0) | F20: =IFERROR(F9/F8,0) | G20: =IFERROR(G9/G8,0) | H20: =IFERROR(H9/H8,0) | I20: =IFERROR(I9/I8,0) | ... N20: =IFERROR(N9/N8,0)
A21: Fruit % of gross revenue | B21: =IFERROR(B11/B8,0) | C21: =IFERROR(C11/C8,0) | D21: =IFERROR(D11/D8,0) | E21: =IFERROR(E11/E8,0) | F21: =IFERROR(F11/F8,0) | G21: =IFERROR(G11/G8,0) | H21: =IFERROR(H11/H8,0) | I21: =IFERROR(I11/I8,0) | ... N21: =IFERROR(N11/N8,0)
A22: Waste % of gross revenue | B22: =IFERROR(B14/B8,0) | C22: =IFERROR(C14/C8,0) | D22: =IFERROR(D14/D8,0) | E22: =IFERROR(E14/E8,0) | F22: =IFERROR(F14/F8,0) | G22: =IFERROR(G14/G8,0) | H22: =IFERROR(H14/H8,0) | I22: =IFERROR(I14/I8,0) | ... N22: =IFERROR(N14/N8,0)

Sheet Kitchen P&L
A1: Kitchen P&L, THB by month
A2: Blue = numbers from the data. Black = formulas. Overhead is fixed per kitchen and never split to items.
A4: BKK_Ladprao
A5: Line | B5: 2025-09 | C5: 2025-10 | D5: 2025-11 | E5: 2025-12 | F5: 2026-01 | G5: 2026-02 | H5: 2026-03 | I5: 2026-04 | J5: 2026-05 | K5: 2026-06 | L5: 2026-07 | M5: 2026-08 | N5: FY
A6: Cups sold | B6: 5961 | C6: 6089 | D6: 6635 | E6: 7338 | F6: 7503 | G6: 6961 | H6: 9999 | I6: 11467 | J6: 9917 | K6: 6827 | L6: 6357 | M6: 6372 | N6: =SUM(B6:M6)
A7: List revenue | B7: 294593 | C7: 301373 | D7: 329191 | E7: 364838 | F7: 372443 | G7: 344017 | H7: 542747 | I7: 606423 | J7: 520425 | K7: 356283 | L7: 329097 | M7: 329868 | N7: =SUM(B7:M7)
A8: Discount | B8: 8734.55 | C8: 6887.07 | D8: 4504 | E8: 4849.35 | F8: 4117.45 | G8: 6178.25 | H8: 8010.75 | I8: 9030 | J8: 9164.85 | K8: 9821.3 | L8: 8295.29 | M8: 7962.04 | N8: =SUM(B8:M8)
A9: Gross revenue | B9: =B7-B8 | C9: =C7-C8 | D9: =D7-D8 | E9: =E7-E8 | F9: =F7-F8 | G9: =G7-G8 | H9: =H7-H8 | I9: =I7-I8 | ... N9: =N7-N8
A10: Commission | B10: 77708.359 | C10: 80222.332 | D10: 87579.204 | E10: 100380.12 | F10: 100698.16 | G10: 92855.685 | H10: 144440.74 | I10: 165930.37 | J10: 140281.47 | K10: 95645.215 | L10: 87656.051 | M10: 86966.321 | N10: =SUM(B10:M10)
A11: Net revenue | B11: =B9-B10 | C11: =C9-C10 | D11: =D9-D10 | E11: =E9-E10 | F11: =F9-F10 | G11: =G9-G10 | H11: =H9-H10 | I11: =I9-I10 | ... N11: =N9-N10
A12: Fruit cost | B12: 61037.46 | C12: 61740.3 | D12: 67189.59 | E12: 75455.96 | F12: 75509.83 | G12: 69801.77 | H12: 128174.22 | I12: 131472.2 | J12: 113025.21 | K12: 89940.61 | L12: 84687.29 | M12: 87994.11 | N12: =SUM(B12:M12)
A13: Packaging + labor | B13: 66860 | C13: 68326.5 | D13: 74495.5 | E13: 82424 | F13: 84292 | G13: 78103 | H13: 116780 | I13: 132396 | J13: 114154.5 | K13: 78371 | L13: 72704 | M13: 72885 | N13: =SUM(B13:M13)
A14: Contribution margin (GP-B) | B14: =B11-B12-B13 | C14: =C11-C12-C13 | D14: =D11-D12-D13 | E14: =E11-E12-E13 | F14: =F11-F12-F13 | G14: =G11-G12-G13 | H14: =H11-H12-H13 | I14: =I11-I12-I13 | ... N14: =N11-N12-N13
A15: Waste cost | B15: 8256.86 | C15: 7782.74 | D15: 8478.65 | E15: 9369.88 | F15: 9501.36 | G15: 9100.89 | H15: 32463.7 | I15: 31171.95 | J15: 26126.838 | K15: 19927.17 | L15: 16469.698 | M15: 17885.33 | N15: =SUM(B15:M15)
A16: Gross profit (GP-C) | B16: =B14-B15 | C16: =C14-C15 | D16: =D14-D15 | E16: =E14-E15 | F16: =F14-F15 | G16: =G14-G15 | H16: =H14-H15 | I16: =I14-I15 | ... N16: =N14-N15
A17: Kitchen overhead | B17: 140000 | C17: 140000 | D17: 140000 | E17: 140000 | F17: 140000 | G17: 140000 | H17: 140000 | I17: 140000 | J17: 140000 | K17: 140000 | L17: 140000 | M17: 140000 | N17: =SUM(B17:M17)
A18: Operating profit | B18: =B16-B17 | C18: =C16-C17 | D18: =D16-D17 | E18: =E16-E17 | F18: =F16-F17 | G18: =G16-G17 | H18: =H16-H17 | I18: =I16-I17 | ... N18: =N16-N17
A19: GP-C % of gross revenue | B19: =IFERROR(B16/B9,0) | C19: =IFERROR(C16/C9,0) | D19: =IFERROR(D16/D9,0) | E19: =IFERROR(E16/E9,0) | F19: =IFERROR(F16/F9,0) | G19: =IFERROR(G16/G9,0) | H19: =IFERROR(H16/H9,0) | I19: =IFERROR(I16/I9,0) | ... N19: =IFERROR(N16/N9,0)
A20: Operating margin % | B20: =IFERROR(B18/B9,0) | C20: =IFERROR(C18/C9,0) | D20: =IFERROR(D18/D9,0) | E20: =IFERROR(E18/E9,0) | F20: =IFERROR(F18/F9,0) | G20: =IFERROR(G18/G9,0) | H20: =IFERROR(H18/H9,0) | I20: =IFERROR(I18/I9,0) | ... N20: =IFERROR(N18/N9,0)
A21: Commission % of gross revenue | B21: =IFERROR(B10/B9,0) | C21: =IFERROR(C10/C9,0) | D21: =IFERROR(D10/D9,0) | E21: =IFERROR(E10/E9,0) | F21: =IFERROR(F10/F9,0) | G21: =IFERROR(G10/G9,0) | H21: =IFERROR(H10/H9,0) | I21: =IFERROR(I10/I9,0) | ... N21: =IFERROR(N10/N9,0)
A22: Fruit % of gross revenue | B22: =IFERROR(B12/B9,0) | C22: =IFERROR(C12/C9,0) | D22: =IFERROR(D12/D9,0) | E22: =IFERROR(E12/E9,0) | F22: =IFERROR(F12/F9,0) | G22: =IFERROR(G12/G9,0) | H22: =IFERROR(H12/H9,0) | I22: =IFERROR(I12/I9,0) | ... N22: =IFERROR(N12/N9,0)
A23: Waste % of gross revenue | B23: =IFERROR(B15/B9,0) | C23: =IFERROR(C15/C9,0) | D23: =IFERROR(D15/D9,0) | E23: =IFERROR(E15/E9,0) | F23: =IFERROR(F15/F9,0) | G23: =IFERROR(G15/G9,0) | H23: =IFERROR(H15/H9,0) | I23: =IFERROR(I15/I9,0) | ... N23: =IFERROR(N15/N9,0)
A26: BKK_Sukhumvit
A27: Line | B27: 2025-09 | C27: 2025-10 | D27: 2025-11 | E27: 2025-12 | F27: 2026-01 | G27: 2026-02 | H27: 2026-03 | I27: 2026-04 | J27: 2026-05 | K27: 2026-06 | L27: 2026-07 | M27: 2026-08 | N27: FY
A28: Cups sold | B28: 9919 | C28: 10197 | D28: 11449 | E28: 12354 | F28: 12239 | G28: 11841 | H28: 16419 | I28: 19128 | J28: 16611 | K28: 11177 | L28: 10716 | M28: 10851 | N28: =SUM(B28:M28)
A29: List revenue | B29: 491755 | C29: 504597 | D29: 566529 | E29: 612874 | F29: 606411 | G29: 586253 | H29: 889551 | I29: 1011648 | J29: 871859 | K29: 586481 | L29: 557024 | M29: 561571 | N29: =SUM(B29:M29)
A30: Discount | B30: 13625.86 | C30: 11172.91 | D30: 7921.7 | E30: 9214.2 | F30: 6692.65 | G30: 10233.1 | H30: 12222.15 | I30: 14738.75 | J30: 15114.45 | K30: 15584.37 | L30: 14059.93 | M30: 13315.76 | N30: =SUM(B30:M30)
A31: Gross revenue | B31: =B29-B30 | C31: =C29-C30 | D31: =D29-D30 | E31: =E29-E30 | F31: =F29-F30 | G31: =G29-G30 | H31: =H29-H30 | I31: =I29-I30 | ... N31: =N29-N30
A32: Commission | B32: 130909.52 | C32: 132818.95 | D32: 152749.39 | E32: 164866.91 | F32: 166179.58 | G32: 158546.29 | H32: 237614.79 | I32: 274495.37 | J32: 231481.16 | K32: 156014.76 | L32: 148977.93 | M32: 147034.79 | N32: =SUM(B32:M32)
A33: Net revenue | B33: =B31-B32 | C33: =C31-C32 | D33: =D31-D32 | E33: =E31-E32 | F33: =F31-F32 | G33: =G31-G32 | H33: =H31-H32 | I33: =I31-I32 | ... N33: =N31-N32
A34: Fruit cost | B34: 102401.69 | C34: 103474.2 | D34: 115220.55 | E34: 126344.62 | F34: 122660.31 | G34: 119526.16 | H34: 209526.08 | I34: 219536.67 | J34: 189024.02 | K34: 149672 | L34: 144825.03 | M34: 149818.88 | N34: =SUM(B34:M34)
A35: Packaging + labor | B35: 111352.5 | C35: 114419.5 | D35: 128449.5 | E35: 138706 | F35: 137395.5 | G35: 132883 | H35: 191463 | I35: 220858 | J35: 191191 | K35: 128507.5 | L35: 122763 | M35: 124114 | N35: =SUM(B35:M35)
A36: Contribution margin (GP-B) | B36: =B33-B34-B35 | C36: =C33-C34-C35 | D36: =D33-D34-D35 | E36: =E33-E34-E35 | F36: =F33-F34-F35 | G36: =G33-G34-G35 | H36: =H33-H34-H35 | I36: =I33-I34-I35 | ... N36: =N33-N34-N35
A37: Waste cost | B37: 8245.5456 | C37: 8164.05 | D37: 9306.3456 | E37: 9585.92 | F37: 9518.7 | G37: 9706.3 | H37: 29866.89 | I37: 31055.7 | J37: 25126.17 | K37: 18854.95 | L37: 16679.52 | M37: 17291.71 | N37: =SUM(B37:M37)
A38: Gross profit (GP-C) | B38: =B36-B37 | C38: =C36-C37 | D38: =D36-D37 | E38: =E36-E37 | F38: =F36-F37 | G38: =G36-G37 | H38: =H36-H37 | I38: =I36-I37 | ... N38: =N36-N37
A39: Kitchen overhead | B39: 200000 | C39: 200000 | D39: 200000 | E39: 200000 | F39: 200000 | G39: 200000 | H39: 200000 | I39: 200000 | J39: 200000 | K39: 200000 | L39: 200000 | M39: 200000 | N39: =SUM(B39:M39)
A40: Operating profit | B40: =B38-B39 | C40: =C38-C39 | D40: =D38-D39 | E40: =E38-E39 | F40: =F38-F39 | G40: =G38-G39 | H40: =H38-H39 | I40: =I38-I39 | ... N40: =N38-N39
A41: GP-C % of gross revenue | B41: =IFERROR(B38/B31,0) | C41: =IFERROR(C38/C31,0) | D41: =IFERROR(D38/D31,0) | E41: =IFERROR(E38/E31,0) | F41: =IFERROR(F38/F31,0) | G41: =IFERROR(G38/G31,0) | H41: =IFERROR(H38/H31,0) | I41: =IFERROR(I38/I31,0) | ... N41: =IFERROR(N38/N31,0)
A42: Operating margin % | B42: =IFERROR(B40/B31,0) | C42: =IFERROR(C40/C31,0) | D42: =IFERROR(D40/D31,0) | E42: =IFERROR(E40/E31,0) | F42: =IFERROR(F40/F31,0) | G42: =IFERROR(G40/G31,0) | H42: =IFERROR(H40/H31,0) | I42: =IFERROR(I40/I31,0) | ... N42: =IFERROR(N40/N31,0)
A43: Commission % of gross revenue | B43: =IFERROR(B32/B31,0) | C43: =IFERROR(C32/C31,0) | D43: =IFERROR(D32/D31,0) | E43: =IFERROR(E32/E31,0) | F43: =IFERROR(F32/F31,0) | G43: =IFERROR(G32/G31,0) | H43: =IFERROR(H32/H31,0) | I43: =IFERROR(I32/I31,0) | ... N43: =IFERROR(N32/N31,0)
...

Sheet Item x Kitchen
A1: Item x kitchen, full year Sep 2025 to Aug 2026, THB
A2: Berry sells from 2026-03-01 only. No overhead here: items are judged on GP-C.
A4: Kitchen | B4: Item | C4: Cups | D4: Gross revenue | E4: Commission | F4: Fruit | G4: Packaging + labor | H4: Waste cups | I4: Waste cost | J4: CM (GP-B) | K4: GP-C | L4: GP-C % | M4: GP-C per cup | N4: Waste rate %
A5: BKK_Ladprao | B5: Guava | C5: 15141 | D5: 727969.48 | E5: 199778.56 | F5: 140838.79 | G5: 174121.5 | H5: 1294 | I5: 19787.49 | J5: =D5-E5-F5-G5 | K5: =J5-I5 | L5: =IFERROR(K5/D5,0) | M5: =IFERROR(K5/C5,0) | N5: =IFERROR(H5/(C5+H5),0)
A6: BKK_Ladprao | B6: MixedBerryPremium | C6: 4163 | D6: 361628.36 | E6: 98924.675 | F6: 158773.75 | G6: 62445 | H6: 1755 | I6: 80899.5 | J6: =D6-E6-F6-G6 | K6: =J6-I6 | L6: =IFERROR(K6/D6,0) | M6: =IFERROR(K6/C6,0) | N6: =IFERROR(H6/(C6+H6),0)
A7: BKK_Ladprao | B7: PassionFruit | C7: 11883 | D7: 758621.5 | E7: 206879.01 | F7: 241954.25 | G7: 142596 | H7: 1709 | I7: 45158.99 | J7: =D7-E7-F7-G7 | K7: =J7-I7 | L7: =IFERROR(K7/D7,0) | M7: =IFERROR(K7/C7,0) | N7: =IFERROR(H7/(C7+H7),0)
A8: BKK_Ladprao | B8: Pineapple | C8: 23933 | D8: 1153733.9 | E8: 314190.54 | F8: 224672.24 | G8: 263263 | H8: 1673 | I8: 25793.33 | J8: =D8-E8-F8-G8 | K8: =J8-I8 | L8: =IFERROR(K8/D8,0) | M8: =IFERROR(K8/C8,0) | N8: =IFERROR(H8/(C8+H8),0)
A9: BKK_Ladprao | B9: Watermelon | C9: 36306 | D9: 1601789.9 | E9: 440591.27 | F9: 279789.52 | G9: 399366 | H9: 1814.9449 | I9: 24895.755 | J9: =D9-E9-F9-G9 | K9: =J9-I9 | L9: =IFERROR(K9/D9,0) | M9: =IFERROR(K9/C9,0) | N9: =IFERROR(H9/(C9+H9),0)
A10: BKK_Sukhumvit | B10: Guava | C10: 25045 | D10: 1204850.2 | E10: 329389.52 | F10: 233300.7 | G10: 288017.5 | H10: 1327.2727 | I10: 20310.661 | J10: =D10-E10-F10-G10 | K10: =J10-I10 | L10: =IFERROR(K10/D10,0) | M10: =IFERROR(K10/C10,0) | N10: =IFERROR(H10/(C10+H10),0)
A11: BKK_Sukhumvit | B11: MixedBerryPremium | C11: 6903 | D11: 600264.06 | E11: 163175.55 | F11: 264236.45 | G11: 103545 | H11: 1630 | I11: 75154.64 | J11: =D11-E11-F11-G11 | K11: =J11-I11 | L11: =IFERROR(K11/D11,0) | M11: =IFERROR(K11/C11,0) | N11: =IFERROR(H11/(C11+H11),0)
A12: BKK_Sukhumvit | B12: PassionFruit | C12: 20057 | D12: 1280316.7 | E12: 350082.6 | F12: 408938.36 | G12: 240684 | H12: 1753 | I12: 46488 | J12: =D12-E12-F12-G12 | K12: =J12-I12 | L12: =IFERROR(K12/D12,0) | M12: =IFERROR(K12/C12,0) | N12: =IFERROR(H12/(C12+H12),0)
A13: BKK_Sukhumvit | B13: Pineapple | C13: 40239 | D13: 1939119.1 | E13: 526608.83 | F13: 377975.09 | G13: 442629 | H13: 1633 | I13: 25122.25 | J13: =D13-E13-F13-G13 | K13: =J13-I13 | L13: =IFERROR(K13/D13,0) | M13: =IFERROR(K13/C13,0) | N13: =IFERROR(H13/(C13+H13),0)
A14: BKK_Sukhumvit | B14: Watermelon | C14: 60657 | D14: 2678107 | E14: 732432.94 | F14: 467579.61 | G14: 667227 | H14: 1918 | I14: 26326.25 | J14: =D14-E14-F14-G14 | K14: =J14-I14 | L14: =IFERROR(K14/D14,0) | M14: =IFERROR(K14/C14,0) | N14: =IFERROR(H14/(C14+H14),0)
A15: Pattaya_Beach | B15: Guava | C15: 28132 | D15: 1353277.6 | E15: 372545.45 | F15: 261914.7 | G15: 323518 | H15: 1482.0604 | I15: 22680.699 | J15: =D15-E15-F15-G15 | K15: =J15-I15 | L15: =IFERROR(K15/D15,0) | M15: =IFERROR(K15/C15,0) | N15: =IFERROR(H15/(C15+H15),0)
A16: Pattaya_Beach | B16: MixedBerryPremium | C16: 7784 | D16: 677538.31 | E16: 184918.59 | F16: 298526.95 | G16: 116760 | H16: 1791 | I16: 82902.37 | J16: =D16-E16-F16-G16 | K16: =J16-I16 | L16: =IFERROR(K16/D16,0) | M16: =IFERROR(K16/C16,0) | N16: =IFERROR(H16/(C16+H16),0)
... A24: Pattaya_Central | B24: Watermelon | C24: 80102 | D24: 3535734.6 | E24: 963945.28 | F24: 617261.74 | G24: 881122 | H24: 2474 | I24: 33896.41 | J24: =D24-E24-F24-G24 | K24: =J24-I24 | L24: =IFERROR(K24/D24,0) | M24: =IFERROR(K24/C24,0) | N24: =IFERROR(H24/(C24+H24),0)
A25: Total | C25: =SUM(C5:C24) | D25: =SUM(D5:D24) | E25: =SUM(E5:E24) | F25: =SUM(F5:F24) | G25: =SUM(G5:G24) | H25: =SUM(H5:H24) | I25: =SUM(I5:I24) | J25: =SUM(J5:J24) | K25: =SUM(K5:K24) | L25: =IFERROR(K25/D25,0) | M25: =IFERROR(K25/C25,0) | N25: =IFERROR(H25/(C25+H25),0)
A26: Check: GP-C minus Company P&L FY (should be 0) | K26: =K25-'Company P&L'!N15

Sheet Budget variance
A1: Actual vs budget by month, THB (GP = GP-C)
A2: GP variance = revenue effect (revenue gap x budget margin) + margin effect (actual revenue x (actual margin - budget margin)). Check column should be 0.
A4: Month | B4: Actual revenue | C4: Budget revenue | D4: Revenue variance | E4: Revenue variance % | F4: Actual GP | G4: Budget GP | H4: GP variance | I4: GP variance % | J4: Actual GP % | K4: Budget GP % | L4: Revenue effect | M4: Margin effect | N4: Check
A5: 2025-09 | B5: ='Company P&L'!B8 | C5: 2700000 | D5: =B5-C5 | E5: =IFERROR(D5/C5,0) | F5: ='Company P&L'!B15 | G5: 700000 | H5: =F5-G5 | I5: =IFERROR(H5/G5,0) | J5: =IFERROR(F5/B5,0) | K5: =IFERROR(G5/C5,0) | L5: =D5*K5 | M5: =F5-B5*K5 | N5: =L5+M5-H5
A6: 2025-10 | B6: ='Company P&L'!C8 | C6: 2700000 | D6: =B6-C6 | E6: =IFERROR(D6/C6,0) | F6: ='Company P&L'!C15 | G6: 700000 | H6: =F6-G6 | I6: =IFERROR(H6/G6,0) | J6: =IFERROR(F6/B6,0) | K6: =IFERROR(G6/C6,0) | L6: =D6*K6 | M6: =F6-B6*K6 | N6: =L6+M6-H6
A7: 2025-11 | B7: ='Company P&L'!D8 | C7: 2700000 | D7: =B7-C7 | E7: =IFERROR(D7/C7,0) | F7: ='Company P&L'!D15 | G7: 700000 | H7: =F7-G7 | I7: =IFERROR(H7/G7,0) | J7: =IFERROR(F7/B7,0) | K7: =IFERROR(G7/C7,0) | L7: =D7*K7 | M7: =F7-B7*K7 | N7: =L7+M7-H7
A8: 2025-12 | B8: ='Company P&L'!E8 | C8: 2700000 | D8: =B8-C8 | E8: =IFERROR(D8/C8,0) | F8: ='Company P&L'!E15 | G8: 700000 | H8: =F8-G8 | I8: =IFERROR(H8/G8,0) | J8: =IFERROR(F8/B8,0) | K8: =IFERROR(G8/C8,0) | L8: =D8*K8 | M8: =F8-B8*K8 | N8: =L8+M8-H8
A9: 2026-01 | B9: ='Company P&L'!F8 | C9: 2700000 | D9: =B9-C9 | E9: =IFERROR(D9/C9,0) | F9: ='Company P&L'!F15 | G9: 700000 | H9: =F9-G9 | I9: =IFERROR(H9/G9,0) | J9: =IFERROR(F9/B9,0) | K9: =IFERROR(G9/C9,0) | L9: =D9*K9 | M9: =F9-B9*K9 | N9: =L9+M9-H9
A10: 2026-02 | B10: ='Company P&L'!G8 | C10: 2700000 | D10: =B10-C10 | E10: =IFERROR(D10/C10,0) | F10: ='Company P&L'!G15 | G10: 700000 | H10: =F10-G10 | I10: =IFERROR(H10/G10,0) | J10: =IFERROR(F10/B10,0) | K10: =IFERROR(G10/C10,0) | L10: =D10*K10 | M10: =F10-B10*K10 | N10: =L10+M10-H10
A11: 2026-03 | B11: ='Company P&L'!H8 | C11: 2700000 | D11: =B11-C11 | E11: =IFERROR(D11/C11,0) | F11: ='Company P&L'!H15 | G11: 700000 | H11: =F11-G11 | I11: =IFERROR(H11/G11,0) | J11: =IFERROR(F11/B11,0) | K11: =IFERROR(G11/C11,0) | L11: =D11*K11 | M11: =F11-B11*K11 | N11: =L11+M11-H11
A12: 2026-04 | B12: ='Company P&L'!I8 | C12: 2700000 | D12: =B12-C12 | E12: =IFERROR(D12/C12,0) | F12: ='Company P&L'!I15 | G12: 700000 | H12: =F12-G12 | I12: =IFERROR(H12/G12,0) | J12: =IFERROR(F12/B12,0) | K12: =IFERROR(G12/C12,0) | L12: =D12*K12 | M12: =F12-B12*K12 | N12: =L12+M12-H12
A13: 2026-05 | B13: ='Company P&L'!J8 | C13: 2700000 | D13: =B13-C13 | E13: =IFERROR(D13/C13,0) | F13: ='Company P&L'!J15 | G13: 700000 | H13: =F13-G13 | I13: =IFERROR(H13/G13,0) | J13: =IFERROR(F13/B13,0) | K13: =IFERROR(G13/C13,0) | L13: =D13*K13 | M13: =F13-B13*K13 | N13: =L13+M13-H13
A14: 2026-06 | B14: ='Company P&L'!K8 | C14: 2700000 | D14: =B14-C14 | E14: =IFERROR(D14/C14,0) | F14: ='Company P&L'!K15 | G14: 700000 | H14: =F14-G14 | I14: =IFERROR(H14/G14,0) | J14: =IFERROR(F14/B14,0) | K14: =IFERROR(G14/C14,0) | L14: =D14*K14 | M14: =F14-B14*K14 | N14: =L14+M14-H14
A15: 2026-07 | B15: ='Company P&L'!L8 | C15: 2700000 | D15: =B15-C15 | E15: =IFERROR(D15/C15,0) | F15: ='Company P&L'!L15 | G15: 700000 | H15: =F15-G15 | I15: =IFERROR(H15/G15,0) | J15: =IFERROR(F15/B15,0) | K15: =IFERROR(G15/C15,0) | L15: =D15*K15 | M15: =F15-B15*K15 | N15: =L15+M15-H15
A16: 2026-08 | B16: ='Company P&L'!M8 | C16: 2700000 | D16: =B16-C16 | E16: =IFERROR(D16/C16,0) | F16: ='Company P&L'!M15 | G16: 700000 | H16: =F16-G16 | I16: =IFERROR(H16/G16,0) | J16: =IFERROR(F16/B16,0) | K16: =IFERROR(G16/C16,0) | L16: =D16*K16 | M16: =F16-B16*K16 | N16: =L16+M16-H16
A17: FY | B17: =SUM(B5:B16) | C17: =SUM(C5:C16) | D17: =B17-C17 | E17: =IFERROR(D17/C17,0) | F17: =SUM(F5:F16) | G17: =SUM(G5:G16) | H17: =F17-G17 | I17: =IFERROR(H17/G17,0) | J17: =IFERROR(F17/B17,0) | K17: =IFERROR(G17/C17,0) | L17: =D17*K17 | M17: =F17-B17*K17 | N17: =L17+M17-H17

Sheet Definitions
A1: Definitions and sources
A3: Source | B3: data/raw/FruitBlend24_Intern_Case_Data.xlsx, cleaned in notebooks 01-02 (see docs/decisions.md).
A4: Period | B4: 2025-09-01 to 2026-08-31. Month = calendar month of the order date.
A5: List revenue | B5: List price x cups. List price = base_price_thb in cost_assumptions.
A6: Discount | B6: List revenue - gross revenue (promo codes RC101, RC102, RC103).
A7: Gross revenue | B7: price_thb x units_sold: what the customer paid, after discount.
A8: Commission | B8: Gross revenue x platform rate (LINE MAN 30%, Grab 24%).
A9: Net revenue | B9: Gross revenue - commission.
A10: Fruit cost | B10: Cups x weekly fruit cost per cup (week = Monday of the order date).
A11: Packaging + labor | B11: Cups x packaging + labor per cup (cost_assumptions).
A12: GP-A | B12: Gross revenue - fruit - packaging + labor (no commission, no waste). Check only.
A13: GP-B / CM | B13: Net revenue - fruit - packaging + labor (no waste). Check only.
A14: Gross profit (GP-C) | B14: GP-B - waste cost. Main definition: waste is a real variable cost and the budget note does not define GP.
... A22: Colors | B22: Blue = numbers from the data. Black = formulas. Green = links to another sheet.
